6EH5_output/correlation_matrix_6EH5.csv
,count_6EH5_Add_Bid,mean_price_6EH5_Add_Bid,median_price_6EH5_Add_Bid,max_price_6EH5_Add_Bid,min_price_6EH5_Add_Bid,var_price_6EH5_Add_Bid,std_price_6EH5_Add_Bid,open_price_6EH5_Add_Bid,close_price_6EH5_Add_Bid,price_change_6EH5_Add_Bid,unique_price_levels_6EH5_Add_Bid,0_6EH5_Add_Bid,1_6EH5_Add_Bid,2_6EH5_Add_Bid,3_6EH5_Add_Bid,4_6EH5_Add_Bid,5_6EH5_Add_Bid,6_6EH5_Add_Bid,7_6EH5_Add_Bid,8_6EH5_Add_Bid,9_6EH5_Add_Bid,10_6EH5_Add_Bid,11_6EH5_Add_Bid,12_6EH5_Add_Bid,13_6EH5_Add_Bid,14_6EH5_Add_Bid,15_6EH5_Add_Bid,16_6EH5_Add_Bid,17_6EH5_Add_Bid,18_6EH5_Add_Bid,19_6EH5_Add_Bid,20_6EH5_Add_Bid,21_6EH5_Add_Bid,count_6EH5_Add_Ask,mean_price_6EH5_Add_Ask,median_price_6EH5_Add_Ask,max_price_6EH5_Add_Ask,min_price_6EH5_Add_Ask,var_price_6EH5_Add_Ask,std_price_6EH5_Add_Ask,open_price_6EH5_Add_Ask,close_price_6EH5_Add_Ask,price_change_6EH5_Add_Ask,unique_price_levels_6EH5_Add_Ask,0_6EH5_Add_Ask,1_6EH5_Add_Ask,2_6EH5_Add_Ask,3_6EH5_Add_Ask,4_6EH5_Add_Ask,5_6EH5_Add_Ask,6_6EH5_Add_Ask,7_6EH5_Add_Ask,8_6EH5_Add_Ask,9_6EH5_Add_Ask,10_6EH5_Add_Ask,11_6EH5_Add_Ask,12_6EH5_Add_Ask,13_6EH5_Add_Ask,14_6EH5_Add_Ask,15_6EH5_Add_Ask,16_6EH5_Add_Ask,17_6EH5_Add_Ask,18_6EH5_Add_Ask,19_6EH5_Add_Ask,20_6EH5_Add_Ask,21_6EH5_Add_Ask,count_6EH5_Modify_Bid,mean_price_6EH5_Modify_Bid,median_price_6EH5_Modify_Bid,max_price_6EH5_Modify_Bid,min_price_6EH5_Modify_Bid,var_price_6EH5_Modify_Bid,std_price_6EH5_Modify_Bid,open_price_6EH5_Modify_Bid,close_price_6EH5_Modify_Bid,price_change_6EH5_Modify_Bid,unique_price_levels_6EH5_Modify_Bid,0_6EH5_Modify_Bid,1_6EH5_Modify_Bid,2_6EH5_Modify_Bid,3_6EH5_Modify_Bid,4_6EH5_Modify_Bid,5_6EH5_Modify_Bid,6_6EH5_Modify_Bid,7_6EH5_Modify_Bid,8_6EH5_Modify_Bid,9_6EH5_Modify_Bid,10_6EH5_Modify_Bid,11_6EH5_Modify_Bid,12_6EH5_Modify_Bid,13_6EH5_Modify_Bid,14_6EH5_Modify_Bid,15_6EH5_Modify_Bid,16_6EH5_Modify_Bid,17_6EH5_Modify_Bid,18_6EH5_Modify_Bid,19_6EH5_Modify_Bid,20_6EH5_Modify_Bid,21_6EH5_Modify_Bid,count_6EH5_Modify_Ask,mean_price_6EH5_Modify_Ask,median_price_6EH5_Modify_Ask,max_price_6EH5_Modify_Ask,min_price_6EH5_Modify_Ask,var_price_6EH5_Modify_Ask,std_price_6EH5_Modify_Ask,open_price_6EH5_Modify_Ask,close_price_6EH5_Modify_Ask,price_change_6EH5_Modify_Ask,unique_price_levels_6EH5_Modify_Ask,0_6EH5_Modify_Ask,1_6EH5_Modify_Ask,2_6EH5_Modify_Ask,3_6EH5_Modify_Ask,4_6EH5_Modify_Ask,5_6EH5_Modify_Ask,6_6EH5_Modify_Ask,7_6EH5_Modify_Ask,8_6EH5_Modify_Ask,9_6EH5_Modify_Ask,10_6EH5_Modify_Ask,11_6EH5_Modify_Ask,12_6EH5_Modify_Ask,13_6EH5_Modify_Ask,14_6EH5_Modify_Ask,15_6EH5_Modify_Ask,16_6EH5_Modify_Ask,17_6EH5_Modify_Ask,18_6EH5_Modify_Ask,19_6EH5_Modify_Ask,20_6EH5_Modify_Ask,21_6EH5_Modify_Ask,count_6EH5_Trade_Bid,mean_price_6EH5_Trade_Bid,median_price_6EH5_Trade_Bid,max_price_6EH5_Trade_Bid,min_price_6EH5_Trade_Bid,var_price_6EH5_Trade_Bid,std_price_6EH5_Trade_Bid,open_price_6EH5_Trade_Bid,close_price_6EH5_Trade_Bid,price_change_6EH5_Trade_Bid,unique_price_levels_6EH5_Trade_Bid,0_6EH5_Trade_Bid,1_6EH5_Trade_Bid,2_6EH5_Trade_Bid,3_6EH5_Trade_Bid,4_6EH5_Trade_Bid,5_6EH5_Trade_Bid,6_6EH5_Trade_Bid,7_6EH5_Trade_Bid,8_6EH5_Trade_Bid,9_6EH5_Trade_Bid,10_6EH5_Trade_Bid,11_6EH5_Trade_Bid,12_6EH5_Trade_Bid,13_6EH5_Trade_Bid,14_6EH5_Trade_Bid,15_6EH5_Trade_Bid,16_6EH5_Trade_Bid,17_6EH5_Trade_Bid,18_6EH5_Trade_Bid,19_6EH5_Trade_Bid,20_6EH5_Trade_Bid,21_6EH5_Trade_Bid,count_6EH5_Trade_Ask,mean_price_6EH5_Trade_Ask,median_price_6EH5_Trade_Ask,max_price_6EH5_Trade_Ask,min_price_6EH5_Trade_Ask,var_price_6EH5_Trade_Ask,std_price_6EH5_Trade_Ask,open_price_6EH5_Trade_Ask,close_price_6EH5_Trade_Ask,price_change_6EH5_Trade_Ask,unique_price_levels_6EH5_Trade_Ask,0_6EH5_Trade_Ask,1_6EH5_Trade_Ask,2_6EH5_Trade_Ask,3_6EH5_Trade_Ask,4_6EH5_Trade_Ask,5_6EH5_Trade_Ask,6_6EH5_Trade_Ask,7_6EH5_Trade_Ask,8_6EH5_Trade_Ask,9_6EH5_Trade_Ask,10_6EH5_Trade_Ask,11_6EH5_Trade_Ask,12_6EH5_Trade_Ask,13_6EH5_Trade_Ask,14_6EH5_Trade_Ask,15_6EH5_Trade_Ask,16_6EH5_Trade_Ask,17_6EH5_Trade_Ask,18_6EH5_Trade_Ask,19_6EH5_Trade_Ask,20_6EH5_Trade_Ask,21_6EH5_Trade_Ask,count_6EH5_Fill_Bid,mean_price_6EH5_Fill_Bid,median_price_6EH5_Fill_Bid,max_price_6EH5_Fill_Bid,min_price_6EH5_Fill_Bid,var_price_6EH5_Fill_Bid,std_price_6EH5_Fill_Bid,open_price_6EH5_Fill_Bid,close_price_6EH5_Fill_Bid,price_change_6EH5_Fill_Bid,unique_price_levels_6EH5_Fill_Bid,0_6EH5_Fill_Bid,1_6EH5_Fill_Bid,2_6EH5_Fill_Bid,3_6EH5_Fill_Bid,4_6EH5_Fill_Bid,5_6EH5_Fill_Bid,6_6EH5_Fill_Bid,7_6EH5_Fill_Bid,8_6EH5_Fill_Bid,9_6EH5_Fill_Bid,10_6EH5_Fill_Bid,11_6EH5_Fill_Bid,12_6EH5_Fill_Bid,13_6EH5_Fill_Bid,14_6EH5_Fill_Bid,15_6EH5_Fill_Bid,16_6EH5_Fill_Bid,17_6EH5_Fill_Bid,18_6EH5_Fill_Bid,19_6EH5_Fill_Bid,20_6EH5_Fill_Bid,21_6EH5_Fill_Bid,count_6EH5_Fill_Ask,mean_price_6EH5_Fill_Ask,median_price_6EH5_Fill_Ask,max_price_6EH5_Fill_Ask,min_price_6EH5_Fill_Ask,var_price_6EH5_Fill_Ask,std_price_6EH5_Fill_Ask,open_price_6EH5_Fill_Ask,close_price_6EH5_Fill_Ask,price_change_6EH5_Fill_Ask,unique_price_levels_6EH5_Fill_Ask,0_6EH5_Fill_Ask,1_6EH5_Fill_Ask,2_6EH5_Fill_Ask,3_6EH5_Fill_Ask,4_6EH5_Fill_Ask,5_6EH5_Fill_Ask,6_6EH5_Fill_Ask,7_6EH5_Fill_Ask,8_6EH5_Fill_Ask,9_6EH5_Fill_Ask,10_6EH5_Fill_Ask,11_6EH5_Fill_Ask,12_6EH5_Fill_Ask,13_6EH5_Fill_Ask,14_6EH5_Fill_Ask,15_6EH5_Fill_Ask,16_6EH5_Fill_Ask,17_6EH5_Fill_Ask,18_6EH5_Fill_Ask,19_6EH5_Fill_Ask,20_6EH5_Fill_Ask,21_6EH5_Fill_Ask
count_6EH5_Add_Bid,1.0,-0.43421354876383494,-0.6270871029696361,-0.4163654660736666,-0.6732129058351486,-0.1289692836958599,-0.031022147195276586,-0.3260542440215958,-0.38692934959173664,-0.07996890840448975,0.6958924233141383,-0.6856319940451899,-0.6968909178561948,0.2949735649943432,-0.7323496820208886,,-0.2519914859424328,0.11338884802830797,-0.169664456439441,0.5643869226576238,0.0019769359095860267,-0.1923710437224174,-0.09567879412402519,0.07028416684337659,-0.56549520124031,0.23339000800538814,-0.7885499377357839,-0.5359664395937517,-0.3451114663019649,-0.3959454542083864,0.5080139497354182,0.2528333197372968,,0.9971081359218583,-0.19145951627303517,-0.7221565744474148,-0.19122729456167864,-0.7675989561250078,-0.19120721046400885,-0.19121588547705895,-0.3836916181915474,-0.30433450722113864,-0.008543369920092256,0.46103346155235836,-0.19123262933810212,-0.1912385567996174,0.8923046756445061,-0.7640851548648958,,0.766638135668974,0.3477671471003322,-0.1912072104994058,-0.5536824450082526,-0.1912165104756489,0.19120724056879373,-0.1998235504374004,0.2603398456559004,-0.5723064880171056,0.08582605930583807,-0.6369470339754215,-0.36927466991379515,0.22358473495922396,-0.2810741607854711,0.574404037751304,0.22538858085661764,,0.9943481489388425,-0.6984935803221273,-0.7587197982593169,-0.4670641552303929,-0.08306138213689311,-0.5301020826296425,-0.5314083591651764,-0.40866560774341176,0.016186506015441873,0.19716663321033687,0.9415296004375892,-0.6351397766204644,-0.7165349665198822,0.6187177607068746,-0.7748975953518165,,,0.055580579420627566,0.0739751550039186,-0.4306664974517606,-0.6576865809740116,0.29336827710364616,-0.6683370520024242,0.27226997444834417,,0.7561431164893078,-0.27077062824123255,-0.507305932137004,0.04613649557364636,0.03239810296787039,0.5090475500488929,0.7729078791187125,,0.9853614281168547,-0.7288623838510421,-0.5995496547465184,-0.31164341296114456,-0.7873246985504216,0.09540154816956943,0.10307705626256451,-0.21587875529895892,-0.553044276267751,-0.3911344367473881,0.8756865999560282,-0.8161785314574268,-0.8087438580339648,0.7945159679184813,-0.8069620647067877,,,0.22666671837631536,0.3293753132177723,-0.17328069063580667,-0.02670298316075026,-0.24478515619954028,0.16936018535376895,-0.08586510124861226,,0.3646291225056718,-0.47497428907746736,-0.46887375883101357,0.11848662114027088,0.059691529161557226,0.47294557106172763,0.8754780803466357,,0.9785534492669604,-0.6988648260260374,-0.723346321358842,-0.468085127903776,-0.7850402086145584,0.9165861133887401,0.93251157046374,-0.4681538628247095,-0.8055979368498493,-0.5738491111133435,0.9578877716774572,-0.7536058931036226,-0.5854858661757105,0.9457357528505282,-0.7525156837855306,,0.9219763729306204,0.9188747352798305,0.9166228106678145,-0.47751524791845223,0.14622082896760785,-0.10417533719792246,-0.7407713255532925,0.5505259638361196,,0.6297191523811829,-0.6632438928507826,-0.6080393544793854,-0.4710835167894367,0.18877720104511478,-0.13456160358883162,0.08440792759790319,,0.9731455238498374,-0.6879406943734435,-0.7087260865810687,-0.4725380187683478,-0.7844693203413196,0.9126221377289404,0.9398520073856476,-0.47351475157650114,-0.8076678208194742,-0.5825868911499761,0.958388330389781,-0.7561087149534199,-0.5803264765851303,0.938800451792727,-0.702939876138859,,0.9085911587480285,0.910105118513964,0.9124681144076575,-0.5595805865639705,0.3570667200038414,0.48635195807428333,0.2796798959809315,0.551783046614631,,0.4022679663828991,-0.6676380408672467,-0.5712907179446002,-0.6745039183890067,0.31435325610282583,0.03865451158432574,0.1358772715710589,,0.9673118234276609,-0.6938703922399695,-0.7093663352431003,-0.4671419836972529,-0.7844693203413196,0.9178945509150535,0.9393300361026657,-0.47351475157650114,-0.8075796237372002,-0.5840719061352937,0.9589567559117002,-0.751576813419239,-0.5762887054988114,0.9356692905901772,-0.6907202913769542,,0.911499853281827,0.9223230251496412,0.9178862921049198,-0.5517819913354363,0.26365076648916624,0.4403151767349669,-0.6136870225107932,0.3278087362111165,,0.24127129205408687,-0.6531406033075232,-0.5610035595788256,-0.6532428399363736,0.009754872991917959,-0.20169359778137327,0.09778794805492481,,0.9783378846500055,-0.6918723856775585,-0.7201608130142014,-0.468085127903776,-0.785133074402743,0.9148504228974809,0.9367510933548264,-0.4675808455253117,-0.8055979368498493,-0.5757280043636729,0.9576095725848666,-0.7529962360451953,-0.5810323415704652,0.9318372406259245,-0.7595293282240603,,0.9178989561280759,0.926863863977766,0.9148362748452561,-0.44208134074526584,0.19524750209857133,-0.13491147887699287,-0.6847092989231862,0.26162166739270915,,0.5050629606151016,-0.6787177795130931,-0.4409975144990487,-0.565276554302408,-0.5924400196174001,-0.26700593982205906,0.12852159298729154,
