6EH5_output/data_6EH5_only.csv
ts_recv,count_6EH5_Add_Bid,mean_price_6EH5_Add_Bid,median_price_6EH5_Add_Bid,max_price_6EH5_Add_Bid,min_price_6EH5_Add_Bid,var_price_6EH5_Add_Bid,std_price_6EH5_Add_Bid,open_price_6EH5_Add_Bid,close_price_6EH5_Add_Bid,price_change_6EH5_Add_Bid,unique_price_levels_6EH5_Add_Bid,0_6EH5_Add_Bid,1_6EH5_Add_Bid,2_6EH5_Add_Bid,3_6EH5_Add_Bid,4_6EH5_Add_Bid,5_6EH5_Add_Bid,6_6EH5_Add_Bid,7_6EH5_Add_Bid,8_6EH5_Add_Bid,9_6EH5_Add_Bid,10_6EH5_Add_Bid,11_6EH5_Add_Bid,12_6EH5_Add_Bid,13_6EH5_Add_Bid,14_6EH5_Add_Bid,15_6EH5_Add_Bid,16_6EH5_Add_Bid,17_6EH5_Add_Bid,18_6EH5_Add_Bid,19_6EH5_Add_Bid,20_6EH5_Add_Bid,21_6EH5_Add_Bid,count_6EH5_Add_Ask,mean_price_6EH5_Add_Ask,median_price_6EH5_Add_Ask,max_price_6EH5_Add_Ask,min_price_6EH5_Add_Ask,var_price_6EH5_Add_Ask,std_price_6EH5_Add_Ask,open_price_6EH5_Add_Ask,close_price_6EH5_Add_Ask,price_change_6EH5_Add_Ask,unique_price_levels_6EH5_Add_Ask,0_6EH5_Add_Ask,1_6EH5_Add_Ask,2_6EH5_Add_Ask,3_6EH5_Add_Ask,4_6EH5_Add_Ask,5_6EH5_Add_Ask,6_6EH5_Add_Ask,7_6EH5_Add_Ask,8_6EH5_Add_Ask,9_6EH5_Add_Ask,10_6EH5_Add_Ask,11_6EH5_Add_Ask,12_6EH5_Add_Ask,13_6EH5_Add_Ask,14_6EH5_Add_Ask,15_6EH5_Add_Ask,16_6EH5_Add_Ask,17_6EH5_Add_Ask,18_6EH5_Add_Ask,19_6EH5_Add_Ask,20_6EH5_Add_Ask,21_6EH5_Add_Ask,count_6EH5_Modify_Bid,mean_price_6EH5_Modify_Bid,median_price_6EH5_Modify_Bid,max_price_6EH5_Modify_Bid,min_price_6EH5_Modify_Bid,var_price_6EH5_Modify_Bid,std_price_6EH5_Modify_Bid,open_price_6EH5_Modify_Bid,close_price_6EH5_Modify_Bid,price_change_6EH5_Modify_Bid,unique_price_levels_6EH5_Modify_Bid,0_6EH5_Modify_Bid,1_6EH5_Modify_Bid,2_6EH5_Modify_Bid,3_6EH5_Modify_Bid,4_6EH5_Modify_Bid,5_6EH5_Modify_Bid,6_6EH5_Modify_Bid,7_6EH5_Modify_Bid,8_6EH5_Modify_Bid,9_6EH5_Modify_Bid,10_6EH5_Modify_Bid,11_6EH5_Modify_Bid,12_6EH5_Modify_Bid,13_6EH5_Modify_Bid,14_6EH5_Modify_Bid,15_6EH5_Modify_Bid,16_6EH5_Modify_Bid,17_6EH5_Modify_Bid,18_6EH5_Modify_Bid,19_6EH5_Modify_Bid,20_6EH5_Modify_Bid,21_6EH5_Modify_Bid,count_6EH5_Modify_Ask,mean_price_6EH5_Modify_Ask,median_price_6EH5_Modify_Ask,max_price_6EH5_Modify_Ask,min_price_6EH5_Modify_Ask,var_price_6EH5_Modify_Ask,std_price_6EH5_Modify_Ask,open_price_6EH5_Modify_Ask,close_price_6EH5_Modify_Ask,price_change_6EH5_Modify_Ask,unique_price_levels_6EH5_Modify_Ask,0_6EH5_Modify_Ask,1_6EH5_Modify_Ask,2_6EH5_Modify_Ask,3_6EH5_Modify_Ask,4_6EH5_Modify_Ask,5_6EH5_Modify_Ask,6_6EH5_Modify_Ask,7_6EH5_Modify_Ask,8_6EH5_Modify_Ask,9_6EH5_Modify_Ask,10_6EH5_Modify_Ask,11_6EH5_Modify_Ask,12_6EH5_Modify_Ask,13_6EH5_Modify_Ask,14_6EH5_Modify_Ask,15_6EH5_Modify_Ask,16_6EH5_Modify_Ask,17_6EH5_Modify_Ask,18_6EH5_Modify_Ask,19_6EH5_Modify_Ask,20_6EH5_Modify_Ask,21_6EH5_Modify_Ask,count_6EH5_Trade_Bid,mean_price_6EH5_Trade_Bid,median_price_6EH5_Trade_Bid,max_price_6EH5_Trade_Bid,min_price_6EH5_Trade_Bid,var_price_6EH5_Trade_Bid,std_price_6EH5_Trade_Bid,open_price_6EH5_Trade_Bid,close_price_6EH5_Trade_Bid,price_change_6EH5_Trade_Bid,unique_price_levels_6EH5_Trade_Bid,0_6EH5_Trade_Bid,1_6EH5_Trade_Bid,2_6EH5_Trade_Bid,3_6EH5_Trade_Bid,4_6EH5_Trade_Bid,5_6EH5_Trade_Bid,6_6EH5_Trade_Bid,7_6EH5_Trade_Bid,8_6EH5_Trade_Bid,9_6EH5_Trade_Bid,10_6EH5_Trade_Bid,11_6EH5_Trade_Bid,12_6EH5_Trade_Bid,13_6EH5_Trade_Bid,14_6EH5_Trade_Bid,15_6EH5_Trade_Bid,16_6EH5_Trade_Bid,17_6EH5_Trade_Bid,18_6EH5_Trade_Bid,19_6EH5_Trade_Bid,20_6EH5_Trade_Bid,21_6EH5_Trade_Bid,count_6EH5_Trade_Ask,mean_price_6EH5_Trade_Ask,median_price_6EH5_Trade_Ask,max_price_6EH5_Trade_Ask,min_price_6EH5_Trade_Ask,var_price_6EH5_Trade_Ask,std_price_6EH5_Trade_Ask,open_price_6EH5_Trade_Ask,close_price_6EH5_Trade_Ask,price_change_6EH5_Trade_Ask,unique_price_levels_6EH5_Trade_Ask,0_6EH5_Trade_Ask,1_6EH5_Trade_Ask,2_6EH5_Trade_Ask,3_6EH5_Trade_Ask,4_6EH5_Trade_Ask,5_6EH5_Trade_Ask,6_6EH5_Trade_Ask,7_6EH5_Trade_Ask,8_6EH5_Trade_Ask,9_6EH5_Trade_Ask,10_6EH5_Trade_Ask,11_6EH5_Trade_Ask,12_6EH5_Trade_Ask,13_6EH5_Trade_Ask,14_6EH5_Trade_Ask,15_6EH5_Trade_Ask,16_6EH5_Trade_Ask,17_6EH5_Trade_Ask,18_6EH5_Trade_Ask,19_6EH5_Trade_Ask,20_6EH5_Trade_Ask,21_6EH5_Trade_Ask,count_6EH5_Fill_Bid,mean_price_6EH5_Fill_Bid,median_price_6EH5_Fill_Bid,max_price_6EH5_Fill_Bid,min_price_6EH5_Fill_Bid,var_price_6EH5_Fill_Bid,std_price_6EH5_Fill_Bid,open_price_6EH5_Fill_Bid,close_price_6EH5_Fill_Bid,price_change_6EH5_Fill_Bid,unique_price_levels_6EH5_Fill_Bid,0_6EH5_Fill_Bid,1_6EH5_Fill_Bid,2_6EH5_Fill_Bid,3_6EH5_Fill_Bid,4_6EH5_Fill_Bid,5_6EH5_Fill_Bid,6_6EH5_Fill_Bid,7_6EH5_Fill_Bid,8_6EH5_Fill_Bid,9_6EH5_Fill_Bid,10_6EH5_Fill_Bid,11_6EH5_Fill_Bid,12_6EH5_Fill_Bid,13_6EH5_Fill_Bid,14_6EH5_Fill_Bid,15_6EH5_Fill_Bid,16_6EH5_Fill_Bid,17_6EH5_Fill_Bid,18_6EH5_Fill_Bid,19_6EH5_Fill_Bid,20_6EH5_Fill_Bid,21_6EH5_Fill_Bid,count_6EH5_Fill_Ask,mean_price_6EH5_Fill_Ask,median_price_6EH5_Fill_Ask,max_price_6EH5_Fill_Ask,min_price_6EH5_Fill_Ask,var_price_6EH5_Fill_Ask,std_price_6EH5_Fill_Ask,open_price_6EH5_Fill_Ask,close_price_6EH5_Fill_Ask,price_change_6EH5_Fill_Ask,unique_price_levels_6EH5_Fill_Ask,0_6EH5_Fill_Ask,1_6EH5_Fill_Ask,2_6EH5_Fill_Ask,3_6EH5_Fill_Ask,4_6EH5_Fill_Ask,5_6EH5_Fill_Ask,6_6EH5_Fill_Ask,7_6EH5_Fill_Ask,8_6EH5_Fill_Ask,9_6EH5_Fill_Ask,10_6EH5_Fill_Ask,11_6EH5_Fill_Ask,12_6EH5_Fill_Ask,13_6EH5_Fill_Ask,14_6EH5_Fill_Ask,15_6EH5_Fill_Ask,16_6EH5_Fill_Ask,17_6EH5_Fill_Ask,18_6EH5_Fill_Ask,19_6EH5_Fill_Ask,20_6EH5_Fill_Ask,21_6EH5_Fill_Ask
2025-01-02 00:00:00,1147.0,1.0336520052310374,1.03675,1.03835,0.7289,0.0003365584689249,0.0183455299439653,1.0375,1.0299,-0.0076,233.0,1.0074050426483154,1.0228774547576904,144.0,0.000871839581517,,2.0,5.0,0.0001723017615319,0.6105243535784852,0.0180873430502483,6.6593009605152485e-06,0.2821983517220707,4.0,0.0087260034904013,44.0,1.6457765064796055,0.0050251256281407,2.918375689890464,0.875,0.875,0.0666666666666666,,1663.0,19.817946061334933,1.0409,10430.0,1.0384,195118.664415223,441.7223838738796,1.0495,1.0384,-0.0111000000000001,323.0,1043.9345703125,522.4865112304688,2.0,0.0006013229104029,,1.0,5.0,34668.696554964714,1.5800002115222105,510.825467321083,-29.33209999754263,3.268049237125117e-06,6.0,0.0114320096269554,5.0,1.6220819400797517,1.0,0.0175081058942912,0.2708333333333333,0.2083333333333333,0.0666960147860459,5.0,,,,,,,,,,,,,,,,,,,,,,,,,,,,,,,,,,,,,,,,,,,,,,,,,,,,,,,,,,,,,,,,,,,,,,,,,,,,,,,,,,,,,,,,,,,,,,,,,,,,,,,,,,,,,,,,,,,,,,,,,,,,,,,,,,,,,,,,,,,,,,,,,,,,,,,,,,,,,,,,,,,,,,,,,,,,,,,,,,,,,,,,,,,,,,,,,,,,,,
2025-01-02 00:30:00,2897.0,1.0378264756644804,1.0382,1.03845,1.02995,2.151248037477332e-06,0.0014667133453668,1.03835,1.0383,-5.000000000010552e-05,95.0,1.037600040435791,1.0380250215530396,114.0,0.0003451846738004,,1.0,2.0,7.693735875262191e-07,1.2087768608538851,0.0015654591653406,9.145696650550188e-11,-3.1086244689505835e-14,1.0,,20.0,1.666696708905459,0.0135135135135135,84.56257505698133,0.8775510204081632,0.2040816326530612,0.0234494849879465,,2525.0,1.0387928316831685,1.03835,1.0492,1.03805,2.497121732751717e-06,0.0015802283799349,1.0384,1.03885,0.00045,103.0,1.0391650199890137,1.0386075973510742,64.0,0.0003960396039604,,1.0,6.0,1.0250672803865416e-06,0.8820389530342436,0.0016357910223932,-1.226245542788774e-10,4.263256414560329e-14,5.0,,4.0,1.6501188335331558,0.0625,84.93467695391003,0.8775510204081632,0.1632653061224489,0.0263972845416311,,1470.0,1.0359885714285713,1.03815,1.03845,1.0277,1.372501906058542e-05,0.0037047292830361,1.03835,1.03825,-0.0001000000000002,49.0,1.0373749732971191,1.0379124879837036,42.0,0.0006802721088434,,1.0,2.0,2.852638170368135e-06,1.5585244804918117,0.0042665825910959,2.23292699115037e-09,-2.287059430727901e-14,1.0,,9.0,2.108912031599014,0.5,62.76025491619514,0.7083333333333334,0.125,0.0114139486768283,,1324.0,1.0411721299093657,1.03845,1.04875,1.0381,1.603550385007986e-05,0.004004435522028,1.0384,1.0384,0.0,52.0,1.0391650199890137,1.0386325120925903,8.0,0.0007552870090634,,1.0,1.0,4.153627844566289e-06,1.4266021327336462,0.0045589738513367,-2.2555799319724313e-09,-7.993605777301223e-15,4.0,,4.0,2.0715098660521294,0.3333333333333333,65.11752472884316,0.4166666666666667,0.1458333333333333,0.010060965681309,,124.0,1.0382830645161287,1.0383,1.03845,1.03805,9.22305271440414e-09,9.603672586257896e-05,1.0384,1.03835,-4.999999999988347e-05,9.0,1.038330078125,1.0382500290870669,22.0,0.0080645161290322,,8.0,15.0,8.084009316560976e-09,0.1472621556370215,5.101590704543462e-05,-6.808943089433383e-14,-8.881784197001264e-16,14.0,,4.0,1.583841129529319,0.032258064516129,6035.024928880029,0.7631578947368421,0.8157894736842105,0.074074074074074,,203.0,1.0382650246305416,1.03825,1.03845,1.03805,7.731063746774879e-09,8.792646783975164e-05,1.0384,1.03835,-4.999999999988347e-05,9.0,1.038330078125,1.0382299423217771,23.0,0.0049261083743842,,16.0,35.0,7.0847820687726e-09,0.0736310778185107,3.954463020156908e-05,2.5371287128782807e-14,3.3306690738754534e-15,24.0,,4.0,1.5671417739645177,0.0384615384615384,8555.338269201633,0.8571428571428571,0.8571428571428571,0.0748299319727891,,361.0,1.0382560941828254,1.03825,1.03845,1.03805,7.1710911049609514e-09,8.468229510919595e-05,1.0384,1.03835,-4.999999999988347e-05,9.0,1.0381700992584229,1.0381900072097778,39.0,0.002770083102493,,26.0,59.0,6.815300490402801e-09,0.0490873852123405,2.980610396015864e-05,1.6319444444482998e-14,5.773159728050764e-15,40.0,,3.0,1.4473058214228849,0.0185185185185185,8727.053863776811,0.8666666666666667,0.8666666666666667,0.0462962962962962,,252.0,1.0382531746031742,1.03825,1.03845,1.03805,9.96996142415056e-09,9.98496941615274e-05,1.0384,1.03835,-4.999999999988347e-05,9.0,1.0381700992584229,1.0381900072097778,33.0,0.0039682539682539,,19.0,30.0,9.43955108164238e-09,0.0490873852123405,3.543972863898571e-05,-3.3366533864554034e-14,-6.661338147750946e-16,29.0,,3.0,1.4796804193648565,0.0185185185185185,6495.337934085426,0.5116279069767442,0.7674418604651163,0.0625,
